Workbook

Sheet KPI Dashboard
A1: Finance Operations KPI Dashboard
A2: Sample workbook (40 stratified merchants) - live formulas, recalculates if source sheets change
A4: Total Expected Revenue | B4: =SUM(tblInvoices[expected_fee])
A5: Total Billed Revenue | B5: =SUM(tblInvoices[billed_fee])
A6: Billing Accuracy % | B6: =ROUND(100*COUNTIF('Invoice Validation'!H4:H1000,"Correct")/COUNTA(tblInvoices[invoice_id]),2)
A7: Total Collected (Payments, Success) | B7: =SUMIFS(tblPayments[payment_amount],tblPayments[payment_status],"Success")
A8: Revenue Realization % | B8: =ROUND(100*B7/B5,2)
A9: Total Outstanding AR | B9: =SUM('AR Aging'!G5:G1000)
A10: Invoices Analyzed | B10: =COUNTA(tblInvoices[invoice_id])
A11: Payments Analyzed | B11: =COUNTA(tblPayments[payment_id])
A12: Merchants in Sample | B12: =COUNTA(tblMerchants[merchant_id])
A14: See other sheets for full detail: Invoices, Payments, Invoice Validation, AR Aging, Collections, Revenue Reconciliation, Monthly MIS.

Sheet Merchants
A1: Merchant Reference (lookup source for XLOOKUP formulas on other sheets)
A3: merchant_id | B3: merchant_name | C3: industry | D3: merchant_segment | E3: city | F3: state | G3: country | H3: onboarding_date | I3: account_manager | J3: pricing_plan | K3: contract_start_date | L3: contract_end_date | M3: agreed_fee_percent | N3: monthly_subscription_fee | O3: payment_terms_days | P3: merchant_status
A4: MER00048 | B4: Martin, Rose and Obrien | C4: Sports & Fitness | D4: Long-tail | E4: Surat | F4: Gujarat | G4: India | H4: 45535 | I4: Pooja Agarwal | J4: Standard | K4: 45535 | M4: 3.41 | N4: 0 | O4: 15 | P4: Active
A5: MER00055 | B5: Jones Inc | C5: Jewellery & Accessories | D5: SMB | E5: Nagpur | F5: Maharashtra | G5: India | H5: 45523 | I5: Priya Nair | J5: Standard | K5: 45523 | M5: 2.69 | N5: 0 | O5: 30 | P5: Active
A6: MER00074 | B6: Stanley, Tucker and Lee | C6: Electronics | D6: Mid-Market | E6: Chandigarh | F6: Chandigarh | G6: India | H6: 45537 | I6: Tanvi Shah | J6: Custom | K6: 45537 | M6: 1.92 | N6: 9999 | O6: 45 | P6: Active
A7: MER00077 | B7: Woods, Calhoun and Schmidt | C7: Fashion & Apparel | D7: SMB | E7: Nagpur | F7: Maharashtra | G7: India | H7: 45522 | I7: Divya Menon | J7: Enterprise | K7: 45522 | M7: 2.22 | N7: 4999 | O7: 15 | P7: Active
A8: MER00139 | B8: Harvey, Davis and Crane | C8: Health & Wellness | D8: Enterprise | E8: Pune | F8: Maharashtra | G8: India | H8: 45525 | I8: Aditya Bose | J8: Enterprise | K8: 45525 | M8: 2 | N8: 4999 | O8: 60 | P8: Active
A9: MER00140 | B9: Chambers and Sons | C9: Home & Living | D9: SMB | E9: Gurugram | F9: Haryana | G9: India | H9: 45511 | I9: Arjun Reddy | J9: Standard | K9: 45511 | M9: 2.57 | N9: 0 | O9: 15 | P9: Active
A10: MER00156 | B10: Hill Inc | C10: Health & Wellness | D10: Long-tail | E10: Noida | F10: Uttar Pradesh | G10: India | H10: 45685 | I10: Divya Menon | J10: Standard | K10: 45685 | M10: 3.25 | N10: 0 | O10: 30 | P10: Active
A11: MER00184 | B11: Higgins, Strickland and Martin | C11: Beauty & Personal Care | D11: Mid-Market | E11: Kochi | F11: Kerala | G11: India | H11: 45518 | I11: Karan Malhotra | J11: Standard | K11: 45518 | L11: 45887 | M11: 2.13 | N11: 0 | O11: 30 | P11: Churned
A12: MER00189 | B12: Garcia LLC | C12: Health & Wellness | D12: Long-tail | E12: Nagpur | F12: Maharashtra | G12: India | H12: 45515 | I12: Arjun Reddy | J12: Standard | K12: 45515 | M12: 2.69 | N12: 0 | O12: 15 | P12: Active
A13: MER00203 | B13: Peterson-Beard | C13: Electronics | D13: SMB | E13: Coimbatore | F13: Tamil Nadu | G13: India | H13: 45521 | I13: Pooja Agarwal | J13: Growth | K13: 45521 | M13: 2.69 | N13: 999 | O13: 30 | P13: Active
A14: MER00346 | B14: Zhang PLC | C14: Fashion & Apparel | D14: Long-tail | E14: Gurugram | F14: Haryana | G14: India | H14: 45539 | I14: Kabir Chatterjee | J14: Growth | K14: 45539 | M14: 3.34 | N14: 999 | O14: 15 | P14: Active
A15: MER00347 | B15: Jones PLC | C15: Jewellery & Accessories | D15: SMB | E15: Noida | F15: Uttar Pradesh | G15: India | H15: 46172 | I15: Arjun Reddy | J15: Growth | K15: 46172 | M15: 2.4 | N15: 999 | O15: 30 | P15: Active
A16: MER00355 | B16: Fisher, Wilson and Brown | C16: Home & Living | D16: Long-tail | E16: Noida | F16: Uttar Pradesh | G16: India | H16: 45526 | I16: Meera Pillai | J16: Standard | K16: 45526 | M16: 2.51 | N16: 0 | O16: 15 | P16: Active
A17: MER00381 | B17: Richardson, Farmer and Andrews | C17: Food & Beverage | D17: SMB | E17: Gurugram | F17: Haryana | G17: India | H17: 45527 | I17: Sneha Iyer | J17: Growth | K17: 45527 | M17: 2.71 | N17: 999 | O17: 15 | P17: Active
A18: MER00386 | B18: Kane PLC | C18: Sports & Fitness | D18: SMB | E18: Ahmedabad | F18: Gujarat | G18: India | H18: 45792 | I18: Priya Nair | J18: Growth | K18: 45792 | M18: 2.35 | N18: 999 | O18: 15 | P18: Active
A19: MER00436 | B19: Cox LLC | C19: Home & Living | D19: Enterprise | E19: Chandigarh | F19: Chandigarh | G19: India | H19: 45535 | I19: Ananya Sharma | J19: Custom | K19: 45535 | M19: 1.96 | N19: 9999 | O19: 45 | P19: Active
A20: MER00457 | B20: Bishop-Goodwin | C20: Electronics | D20: Long-tail | E20: Chennai | F20: Tamil Nadu | G20: India | H20: 45518 | I20: Divya Menon | J20: Growth | K20: 45518 | M20: 3.11 | N20: 999 | O20: 15 | P20: Active
A21: MER00480 | B21: Barnes PLC | C21: Electronics | D21: SMB | E21: Nagpur | F21: Maharashtra | G21: India | H21: 45511 | I21: Priya Nair | J21: Standard | K21: 45511 | M21: 2.61 | N21: 0 | O21: 30 | P21: Active
A22: MER00484 | B22: Mendez and Sons | C22: Sports & Fitness | D22: Long-tail | E22: Surat | F22: Gujarat | G22: India | H22: 45529 | I22: Siddharth Joshi | J22: Standard | K22: 45529 | M22: 3.21 | N22: 0 | O22: 30 | P22: Active
A23: MER00502 | B23: Paul-Kline | C23: Food & Beverage | D23: SMB | E23: Surat | F23: Gujarat | G23: India | H23: 45528 | I23: Priya Nair | J23: Growth | K23: 45528 | M23: 2.7 | N23: 999 | O23: 15 | P23: Active
... A43: MER00902 | B43: Griffith, Mitchell and Pugh | C43: Fashion & Apparel | D43: Mid-Market | E43: Chandigarh | F43: Chandigarh | G43: India | H43: 45529 | I43: Pooja Agarwal | J43: Growth | K43: 45529 | M43: 1.86 | N43: 999 | O43: 30 | P43: Active

Sheet Raw Transactions
A1: Raw Transactions (sampled: 2,500 of the full dataset for these merchants)
A3: transaction_id | B3: merchant_id | C3: transaction_date | D3: order_id | E3: transaction_amount | F3: transaction_fee_percent | G3: expected_platform_fee | H3: payment_method | I3: payment_status | J3: order_status | K3: refund_amount | L3: discount_amount | M3: currency | N3: created_timestamp
A4: TXN00005842 | B4: MER00048 | C4: 45529 | D4: ORD00005842 | E4: 1086.34 | F4: 2.5 | G4: 27.16 | H4: NetBanking | I4: Success | J4: Delivered | K4: 0 | L4: 0 | M4: INR | N4: 2024-08-25 11:40:02
A5: TXN00012021 | B5: MER00048 | C5: 45551 | D5: ORD00012021 | E5: 813.81 | F5: 3.41 | G5: 27.75 | H5: UPI | I5: Success | J5: Delivered | K5: 0 | L5: 0 | M5: INR | N5: 2024-09-16 16:50:30
A6: TXN00027065 | B6: MER00048 | C6: 45594 | D6: ORD00027065 | E6: 1613.07 | F6: 3.41 | G6: 55.01 | H6: Card | I6: Success | J6: Returned | K6: 880.93 | L6: 0 | M6: INR | N6: 2024-10-29 04:27:47
A7: TXN00030133 | B7: MER00048 | C7: 45601 | D7: ORD00030133 | E7: 3904.39 | F7: 3.41 | G7: 133.14 | H7: UPI | I7: Success | J7: Delivered | K7: 0 | L7: 0 | M7: INR | N7: 2024-11-05 14:31:54
A8: TXN00069246 | B8: MER00048 | C8: 45707 | D8: ORD00069246 | E8: 2134.51 | F8: 3.41 | G8: 72.79 | H8: UPI | I8: Pending | J8: Processing | K8: 0 | L8: 205.69 | M8: INR | N8: 2025-02-19 20:19:36
A9: TXN00074371 | B9: MER00048 | C9: 45723 | D9: ORD00074371 | E9: 1437.74 | F9: 3.41 | G9: 49.03 | H9: Card | I9: Success | J9: Delivered | K9: 0 | L9: 0 | M9: INR | N9: 2025-03-07 21:16:56
A10: TXN00093558 | B10: MER00048 | C10: 45782 | D10: ORD00093558 | E10: 1275.62 | F10: 3.41 | G10: 43.5 | H10: UPI | I10: Success | J10: Cancelled | K10: 1269.78 | L10: 0 | M10: INR | N10: 2025-05-05 23:19:04
A11: TXN00098341 | B11: MER00048 | C11: 45797 | D11: ORD00098341 | E11: 2331.89 | F11: 3.41 | G11: 79.52 | H11: UPI | I11: Success | J11: Returned | K11: 1784.53 | L11: 378.59 | M11: INR | N11: 2025-05-20 03:19:12
A12: TXN00130791 | B12: MER00048 | C12: 45894 | D12: ORD00130791 | E12: 2316.69 | F12: 3.41 | G12: 79 | H12: UPI | I12: Success | J12: Delivered | K12: 0 | L12: 0 | M12: INR | N12: 2025-08-25 10:21:02
A13: TXN00136801 | B13: MER00048 | C13: 45911 | D13: ORD00136801 | E13: 2035.75 | F13: 3.41 | G13: 69.42 | H13: Card | I13: Success | J13: Delivered | K13: 0 | L13: 0 | M13: INR | N13: 2025-09-11 22:27:17
A14: TXN00188216 | B14: MER00048 | C14: 46027 | D14: ORD00188216 | E14: 622.62 | F14: 3.41 | G14: 21.23 | H14: Card | I14: Success | J14: Delivered | K14: 0 | L14: 0 | M14: INR | N14: 2026-01-05 16:55:59
A15: TXN00206757 | B15: MER00048 | C15: 46069 | D15: ORD00206757 | E15: 844.84 | F15: 3.41 | G15: 28.81 | H15: Card | I15: Success | J15: Delivered | K15: 0 | L15: 0 | M15: INR | N15: 2026-02-16 22:10:23
... A2503: TXN00263343 | B2503: MER00902 | C2503: 46216 | D2503: ORD00263343 | E2503: 2513.65 | F2503: 1.86 | G2503: 46.75 | H2503: UPI | I2503: Success | J2503: Delivered | K2503: 0 | L2503: 0 | M2503: INR | N2503: 2026-07-13 16:35:18

Sheet Invoices
A1: Invoices
A3: invoice_id | B3: merchant_id | C3: billing_period_start | D3: billing_period_end | E3: invoice_date | F3: due_date | G3: subtotal | H3: discount | I3: taxable_amount | J3: tax_rate | K3: tax_amount | L3: total_invoice_amount | M3: currency | N3: invoice_status | O3: payment_status | P3: expected_fee | Q3: billed_fee | R3: invoice_error_flag
A4: INV0000956 | B4: MER00048 | C4: 2024-08-01 | D4: 2024-08-31 | E4: 45537 | F4: 45552 | G4: 80.15 | H4: 0 | I4: 80.15 | J4: 0.18 | K4: 14.43 | L4: 94.58 | M4: INR | N4: Paid | O4: Paid | P4: 80.15 | Q4: 80.15 | R4: FALSE
A5: INV0000957 | B5: MER00048 | C5: 2024-09-01 | D5: 2024-09-30 | E5: 45567 | F5: 45582 | G5: 326.04 | H5: 0 | I5: 326.04 | J5: 0.18 | K5: 58.69 | L5: 384.73 | M5: INR | N5: Paid | O5: Paid | P5: 326.04 | Q5: 326.04 | R5: FALSE
A6: INV0000958 | B6: MER00048 | C6: 2024-10-01 | D6: 2024-10-31 | E6: 45598 | F6: 45613 | G6: 258.85 | H6: 0 | I6: 258.85 | J6: 0.18 | K6: 46.59 | L6: 305.44 | M6: INR | N6: Paid | O6: Paid | P6: 258.85 | Q6: 258.85 | R6: FALSE
A7: INV0000959 | B7: MER00048 | C7: 2024-11-01 | D7: 2024-11-30 | E7: 45628 | F7: 45643 | G7: 511.05 | H7: 0 | I7: 511.05 | J7: 0.18 | K7: 91.99 | L7: 603.04 | M7: INR | N7: Paid | O7: Paid | P7: 511.05 | Q7: 511.05 | R7: FALSE
A8: INV0000960 | B8: MER00048 | C8: 2024-12-01 | D8: 2024-12-31 | E8: 45659 | F8: 45674 | G8: 55.69 | H8: 0 | I8: 55.69 | J8: 0.18 | K8: 10.02 | L8: 65.71 | M8: INR | N8: Paid | O8: Paid | P8: 67.41 | Q8: 55.69 | R8: TRUE
A9: INV0000961 | B9: MER00048 | C9: 2025-01-01 | D9: 2025-01-31 | E9: 45690 | F9: 45705 | G9: 160.14 | H9: 12.49 | I9: 147.65 | J9: 0.18 | K9: 26.58 | L9: 174.23 | M9: INR | N9: Paid | O9: Paid | P9: 160.14 | Q9: 160.14 | R9: FALSE
A10: INV0000962 | B10: MER00048 | C10: 2025-02-01 | D10: 2025-02-28 | E10: 45718 | F10: 45733 | G10: 162.38 | H10: 0 | I10: 162.38 | J10: 0.18 | K10: 29.23 | L10: 191.61 | M10: INR | N10: Paid | O10: Paid | P10: 162.38 | Q10: 162.38 | R10: FALSE
A11: INV0000963 | B11: MER00048 | C11: 2025-03-01 | D11: 2025-03-31 | E11: 45749 | F11: 45764 | G11: 101.64 | H11: 0 | I11: 101.64 | J11: 0.18 | K11: 18.3 | L11: 119.94 | M11: INR | N11: Paid | O11: Paid | P11: 101.64 | Q11: 101.64 | R11: FALSE
A12: INV0000964 | B12: MER00048 | C12: 2025-04-01 | D12: 2025-04-30 | E12: 45779 | F12: 45794 | G12: 315.45 | H12: 43.53 | I12: 271.92 | J12: 0.18 | K12: 48.95 | L12: 320.87 | M12: INR | N12: Paid | O12: Paid | P12: 315.45 | Q12: 315.45 | R12: FALSE
A13: INV0000965 | B13: MER00048 | C13: 2025-05-01 | D13: 2025-05-31 | E13: 45810 | F13: 45825 | G13: 287.68 | H13: 0 | I13: 287.68 | J13: 0.18 | K13: 51.78 | L13: 339.46 | M13: INR | N13: Paid | O13: Paid | P13: 287.68 | Q13: 287.68 | R13: FALSE
A14: INV0000966 | B14: MER00048 | C14: 2025-07-01 | D14: 2025-07-31 | E14: 45871 | F14: 45886 | G14: 168.49 | H14: 0 | I14: 168.49 | J14: 0.18 | K14: 30.33 | L14: 198.82 | M14: INR | N14: Paid | O14: Paid | P14: 168.49 | Q14: 168.49 | R14: FALSE
A15: INV0000967 | B15: MER00048 | C15: 2025-08-01 | D15: 2025-08-31 | E15: 45902 | F15: 45917 | G15: 166.18 | H15: 19.78 | I15: 146.4 | J15: 0.18 | K15: 26.35 | L15: 172.75 | M15: INR | N15: Paid | O15: Paid | P15: 166.18 | Q15: 166.18 | R15: FALSE
... A898: INV0019140 | B898: MER00902 | C898: 2026-07-01 | D898: 2026-07-31 | E898: 46236 | F898: 46266 | G898: 530.76 | H898: 0 | I898: 530.76 | J898: 0.18 | K898: 95.54 | L898: 626.3 | M898: INR | N898: Paid | O898: Paid | P898: 530.76 | Q898: 530.76 | R898: FALSE

Sheet Payments
A1: Payments
A3: payment_id | B3: invoice_id | C3: merchant_id | D3: payment_date | E3: payment_amount | F3: payment_method | G3: payment_reference | H3: payment_status | I3: bank_reference | J3: settlement_date
A4: PAY0000165 | B4: INV0000956 | C4: MER00048 | D4: 45549 | E4: 94.58 | F4: Card | G4: PAYMKP6KQR24E | H4: Success | I4: BNKMQ2KPJLA326D | J4: 45550
A5: PAY0000166 | B5: INV0000957 | C5: MER00048 | D5: 45579 | E5: 384.73 | F5: UPI | G5: PAYG38QBVMBUN | H5: Success | I5: BNK8G4PL86ZH5QB | J5: 45582
A6: PAY0000167 | B6: INV0000958 | C6: MER00048 | D6: 45608 | E6: 305.44 | F6: UPI | G6: PAYX4QSV4PCFH | H6: Success | I6: BNKJBTGPFPUWDWP | J6: 45609
A7: PAY0000168 | B7: INV0000959 | C7: MER00048 | D7: 45635 | E7: 603.04 | F7: Card | G7: PAYLMV9CN64BX | H7: Success | I7: BNKRLQMHTYN84L3 | J7: 45636
A8: PAY0000169 | B8: INV0000960 | C8: MER00048 | D8: 45675 | E8: 65.71 | F8: Card | G8: PAYQMR34A2NF6 | H8: Success | I8: BNKNJ695DMUQW8S | J8: 45677
A9: PAY0000170 | B9: INV0000962 | C9: MER00048 | D9: 45734 | E9: 191.61 | F9: UPI | G9: PAYXNTPE9KLN5 | H9: Success | I9: BNK8GAARTLR8H76 | J9: 45735
A10: PAY0000171 | B10: INV0000963 | C10: MER00048 | D10: 45764 | E10: 119.94 | F10: UPI | G10: PAYRBFLRYWH7T | H10: Success | I10: BNKA8VLKDZLQSZC | J10: 45766
A11: PAY0000172 | B11: INV0000964 | C11: MER00048 | D11: 45789 | E11: 320.87 | F11: UPI | G11: PAYKVUZN2JTAE | H11: Success | I11: BNK48JEDJKBTVDZ | J11: 45791
A12: PAY0000173 | B12: INV0000965 | C12: MER00048 | D12: 45825 | E12: 339.46 | F12: UPI | G12: PAYD9KANKTU6U | H12: Success | I12: BNK39DUPLVEV8C4 | J12: 45826
A13: PAY0000174 | B13: INV0000966 | C13: MER00048 | D13: 45886 | E13: 198.82 | F13: Card | G13: PAY6R8VLDQWAH | H13: Success | I13: BNKB25HV2UNXHX9 | J13: 45889
A14: PAY0000175 | B14: INV0000967 | C14: MER00048 | D14: 45915 | E14: 172.75 | F14: UPI | G14: PAY9FGL2LWD4R | H14: Success | I14: BNKYY5J537M8D2B | J14: 45917
A15: PAY0000176 | B15: INV0000968 | C15: MER00048 | D15: 45939 | E15: 345.26 | F15: UPI | G15: PAY9E2DJMHQ39 | H15: Success | I15: BNKY9LYTPNAG6UZ | J15: 45942
... A54: PAY0001850 | B54: INV0008129 | C54: MER00386 | D54: 46003 | E54: 582.74 | F54: UPI | G54: PAYC6M6T355MZ | H54: Success | I54: BNK3M6TDTFC74JQ | J54: 46004
A55: PAY0001851 | B55: INV0008130 | C55: MER00386 | D55: 46034 | E55: 703.17 | F55: UPI | G55: PAY43DE56TVKJ | H55: Failed | I55: BNKNXALCXR45KYK
A56: PAY0001852 | B56: INV0008131 | C56: MER00386 | D56: 46093 | E56: 673.14 | F56: UPI | G56: PAYZT6TXHWX6V | H56: Success | I56: BNKD9LZ2KUHY3EP | J56: 46096
A57: PAY0001853 | B57: INV0008132 | C57: MER00386 | D57: 46132 | E57: 772.69 | F57: UPI | G57: PAYECRJR8FTMU | H57: Success | I57: BNK6KX95VH4J3W5 | J57: 46133
A58: PAY0001854 | B58: INV0008133 | C58: MER00386 | D58: 46160 | E58: 519.7 | F58: Card | G58: PAY8UGMCRGGR2 | H58: Success | I58: BNK3P6MUZXEGY2K | J58: 46163
A59: PAY0001855 | B59: INV0008134 | C59: MER00386 | D59: 46190 | E59: 367.03 | F59: NetBanking | G59: PAYCCH8WFSZFN | H59: Success | I59: BNK25AVC3UL49MG | J59: 46193
A60: PAY0001856 | B60: INV0008135 | C60: MER00386 | D60: 46214 | E60: 494.34 | F60: UPI | G60: PAY6S5KRUJ9WV | H60: Success | I60: BNKGBTEKY44W6EJ | J60: 46216
A61: PAY0001857 | B61: INV0008136 | C61: MER00386 | D61: 46245 | E61: 586.4 | F61: UPI | G61: PAYUPFED4ZM3U | H61: Success | I61: BNKQHKB4KKMYNC2 | J61: 46246
A62: PAY0002060 | B62: INV0009199 | C62: MER00436 | D62: 45582 | E62: 3151.01 | F62: UPI | G62: PAYPJREJCG472 | H62: Success | I62: BNKFPU48769M2CR | J62: 45585
A63: PAY0002061 | B63: INV0009200 | C63: MER00436 | D63: 45611 | E63: 2210.45 | F63: Card | G63: PAYJRJ27KRFWQ | H63: Success | I63: BNK982SDYU5GAB5 | J63: 45614
A64: PAY0002062 | B64: INV0009201 | C64: MER00436 | D64: 45640 | E64: 3622.79 | F64: Card | G64: PAY2S4K5Y53PF | H64: Success | I64: BNKL8WFY7G48SAN | J64: 45643
A65: PAY0002063 | B65: INV0009202 | C65: MER00436 | D65: 45666 | E65: 2817.46 | F65: UPI | G65: PAYUMUGG744GT | H65: Success | I65: BNKH3B32GVSGXGY | J65: 45669
A66: PAY0002064 | B66: INV0009203 | C66: MER00436 | D66: 45706 | E66: 2967.03 | F66: UPI | G66: PAYFLJR4AGGUA | H66: Success | I66: BNKZ4PGG3UBTYEY | J66: 45708
A67: PAY0002065 | B67: INV0009204 | C67: MER00436 | D67: 45731 | E67: 3438.18 | F67: UPI | G67: PAYPG5RE86663 | H67: Success | I67: BNKDFNTYB4EP3DX | J67: 45733
... A209: PAY0004402 | B209: INV0018134 | C209: MER00856 | D209: 46052 | E209: 283.88 | F209: NetBanking | G209: PAYTPXQMTKCWN | H209: Success | I209: BNKP8ZN3SRS2J9N | J209: 46054
A210: PAY0004403 | B210: INV0018135 | C210: MER00856 | D210: 46082 | E210: 190.36 | F210: Card | G210: PAYHQ6U6D9YUS | H210: Failed | I210: BNKH4KYR35GZ2NW
A211: PAY0004404 | B211: INV0018136 | C211: MER00856 | D211: 46110 | E211: 167.93 | F211: Card | G211: PAYUSKHQEWFV5 | H211: Success | I211: BNKQZG7LAWWHRVV | J211: 46111
A212: PAY0004405 | B212: INV0018137 | C212: MER00856 | D212: 46144 | E212: 105.43 | F212: UPI | G212: PAYU6GP5KRHTW | H212: Success | I212: BNKK32SFKE6TAQ6 | J212: 46146
A213: PAY0004406 | B213: INV0018138 | C213: MER00856 | D213: 46173 | E213: 90.49 | F213: UPI | G213: PAY9MTSAVML6N | H213: Success | I213: BNKLMZYCP3MAGCH | J213: 46174
A214: PAY0004407 | B214: INV0018140 | C214: MER00856 | D214: 46235 | E214: 125.25 | F214: UPI | G214: PAYBHHM474TVE | H214: Success | I214: BNKDRNE3E252GJ6 | J214: 46238
A215: PAY0004408 | B215: INV0018141 | C215: MER00856 | D215: 46263 | E215: 185.17 | F215: Card | G215: PAYXHYX49Z8HC | H215: Success | I215: BNKT4926YA6UJML | J215: 46266
A216: PAY0004433 | B216: INV0018395 | C216: MER00870 | D216: 45593 | E216: 246.95 | F216: UPI | G216: PAY43H5LPK56D | H216: Success | I216: BNKLMMUDEFE3X5F | J216: 45595
A217: PAY0004434 | B217: INV0018396 | C217: MER00870 | D217: 45628 | E217: 209.95 | F217: UPI | G217: PAY9KNLA67CAF | H217: Success | I217: BNKFK26RUQ3LWLE | J217: 45631
A218: PAY0004435 | B218: INV0018397 | C218: MER00870 | D218: 45660 | E218: 94.88 | F218: UPI | G218: PAYKGHJHVUK8N | H218: Success | I218: BNKQ2VBRW4SED5P | J218: 45661
A219: PAY0004436 | B219: INV0018398 | C219: MER00870 | D219: 45684 | E219: 69.23 | F219: COD | G219: PAYD8ZSDF3EK4 | H219: Success | I219: BNKCJ5WWL4Y2XGC | J219: 45686
A220: PAY0004437 | B220: INV0018399 | C220: MER00870 | D220: 45721 | E220: 545.94 | F220: UPI | G220: PAYR8LE8AATRD | H220: Success | I220: BNK9P7ALN9EM7XJ | J220: 45722
...

Sheet Invoice Validation
A1: Invoice Validation - expected vs. billed, with XLOOKUP + IF formulas
A3: invoice_id | B3: merchant_id | C3: merchant_name | D3: expected_fee | E3: billed_fee | F3: revenue_difference | G3: variance_percent | H3: billing_status | I3: review_status
A4: INV0000956 | B4: MER00048 | C4: =XLOOKUP(B4,Merchants!$A$4:$A$1000,Merchants!$B$4:$B$1000,"Not found") | D4: =XLOOKUP(A4,tblInvoices[invoice_id],tblInvoices[expected_fee]) | E4: =XLOOKUP(A4,tblInvoices[invoice_id],tblInvoices[billed_fee]) | F4: =E4-D4 | G4: =IF(D4=0,0,ROUND(100*F4/D4,2)) | H4: =IF(ABS(F4)<=0.01,"Correct",IF(F4<0,"Underbilled","Overbilled"))
A5: INV0000957 | B5: MER00048 | C5: =XLOOKUP(B5,Merchants!$A$4:$A$1000,Merchants!$B$4:$B$1000,"Not found") | D5: =XLOOKUP(A5,tblInvoices[invoice_id],tblInvoices[expected_fee]) | E5: =XLOOKUP(A5,tblInvoices[invoice_id],tblInvoices[billed_fee]) | F5: =E5-D5 | G5: =IF(D5=0,0,ROUND(100*F5/D5,2)) | H5: =IF(ABS(F5)<=0.01,"Correct",IF(F5<0,"Underbilled","Overbilled"))
A6: INV0000958 | B6: MER00048 | C6: =XLOOKUP(B6,Merchants!$A$4:$A$1000,Merchants!$B$4:$B$1000,"Not found") | D6: =XLOOKUP(A6,tblInvoices[invoice_id],tblInvoices[expected_fee]) | E6: =XLOOKUP(A6,tblInvoices[invoice_id],tblInvoices[billed_fee]) | F6: =E6-D6 | G6: =IF(D6=0,0,ROUND(100*F6/D6,2)) | H6: =IF(ABS(F6)<=0.01,"Correct",IF(F6<0,"Underbilled","Overbilled"))
A7: INV0000959 | B7: MER00048 | C7: =XLOOKUP(B7,Merchants!$A$4:$A$1000,Merchants!$B$4:$B$1000,"Not found") | D7: =XLOOKUP(A7,tblInvoices[invoice_id],tblInvoices[expected_fee]) | E7: =XLOOKUP(A7,tblInvoices[invoice_id],tblInvoices[billed_fee]) | F7: =E7-D7 | G7: =IF(D7=0,0,ROUND(100*F7/D7,2)) | H7: =IF(ABS(F7)<=0.01,"Correct",IF(F7<0,"Underbilled","Overbilled"))
A8: INV0000960 | B8: MER00048 | C8: =XLOOKUP(B8,Merchants!$A$4:$A$1000,Merchants!$B$4:$B$1000,"Not found") | D8: =XLOOKUP(A8,tblInvoices[invoice_id],tblInvoices[expected_fee]) | E8: =XLOOKUP(A8,tblInvoices[invoice_id],tblInvoices[billed_fee]) | F8: =E8-D8 | G8: =IF(D8=0,0,ROUND(100*F8/D8,2)) | H8: =IF(ABS(F8)<=0.01,"Correct",IF(F8<0,"Underbilled","Overbilled"))
A9: INV0000961 | B9: MER00048 | C9: =XLOOKUP(B9,Merchants!$A$4:$A$1000,Merchants!$B$4:$B$1000,"Not found") | D9: =XLOOKUP(A9,tblInvoices[invoice_id],tblInvoices[expected_fee]) | E9: =XLOOKUP(A9,tblInvoices[invoice_id],tblInvoices[billed_fee]) | F9: =E9-D9 | G9: =IF(D9=0,0,ROUND(100*F9/D9,2)) | H9: =IF(ABS(F9)<=0.01,"Correct",IF(F9<0,"Underbilled","Overbilled"))
A10: INV0000962 | B10: MER00048 | C10: =XLOOKUP(B10,Merchants!$A$4:$A$1000,Merchants!$B$4:$B$1000,"Not found") | D10: =XLOOKUP(A10,tblInvoices[invoice_id],tblInvoices[expected_fee]) | E10: =XLOOKUP(A10,tblInvoices[invoice_id],tblInvoices[billed_fee]) | F10: =E10-D10 | G10: =IF(D10=0,0,ROUND(100*F10/D10,2)) | H10: =IF(ABS(F10)<=0.01,"Correct",IF(F10<0,"Underbilled","Overbilled"))
A11: INV0000963 | B11: MER00048 | C11: =XLOOKUP(B11,Merchants!$A$4:$A$1000,Merchants!$B$4:$B$1000,"Not found") | D11: =XLOOKUP(A11,tblInvoices[invoice_id],tblInvoices[expected_fee]) | E11: =XLOOKUP(A11,tblInvoices[invoice_id],tblInvoices[billed_fee]) | F11: =E11-D11 | G11: =IF(D11=0,0,ROUND(100*F11/D11,2)) | H11: =IF(ABS(F11)<=0.01,"Correct",IF(F11<0,"Underbilled","Overbilled"))
A12: INV0000964 | B12: MER00048 | C12: =XLOOKUP(B12,Merchants!$A$4:$A$1000,Merchants!$B$4:$B$1000,"Not found") | D12: =XLOOKUP(A12,tblInvoices[invoice_id],tblInvoices[expected_fee]) | E12: =XLOOKUP(A12,tblInvoices[invoice_id],tblInvoices[billed_fee]) | F12: =E12-D12 | G12: =IF(D12=0,0,ROUND(100*F12/D12,2)) | H12: =IF(ABS(F12)<=0.01,"Correct",IF(F12<0,"Underbilled","Overbilled"))
A13: INV0000965 | B13: MER00048 | C13: =XLOOKUP(B13,Merchants!$A$4:$A$1000,Merchants!$B$4:$B$1000,"Not found") | D13: =XLOOKUP(A13,tblInvoices[invoice_id],tblInvoices[expected_fee]) | E13: =XLOOKUP(A13,tblInvoices[invoice_id],tblInvoices[billed_fee]) | F13: =E13-D13 | G13: =IF(D13=0,0,ROUND(100*F13/D13,2)) | H13: =IF(ABS(F13)<=0.01,"Correct",IF(F13<0,"Underbilled","Overbilled"))
A14: INV0000966 | B14: MER00048 | C14: =XLOOKUP(B14,Merchants!$A$4:$A$1000,Merchants!$B$4:$B$1000,"Not found") | D14: =XLOOKUP(A14,tblInvoices[invoice_id],tblInvoices[expected_fee]) | E14: =XLOOKUP(A14,tblInvoices[invoice_id],tblInvoices[billed_fee]) | F14: =E14-D14 | G14: =IF(D14=0,0,ROUND(100*F14/D14,2)) | H14: =IF(ABS(F14)<=0.01,"Correct",IF(F14<0,"Underbilled","Overbilled"))
A15: INV0000967 | B15: MER00048 | C15: =XLOOKUP(B15,Merchants!$A$4:$A$1000,Merchants!$B$4:$B$1000,"Not found") | D15: =XLOOKUP(A15,tblInvoices[invoice_id],tblInvoices[expected_fee]) | E15: =XLOOKUP(A15,tblInvoices[invoice_id],tblInvoices[billed_fee]) | F15: =E15-D15 | G15: =IF(D15=0,0,ROUND(100*F15/D15,2)) | H15: =IF(ABS(F15)<=0.01,"Correct",IF(F15<0,"Underbilled","Overbilled"))
... A898: INV0019140 | B898: MER00902 | C898: =XLOOKUP(B898,Merchants!$A$4:$A$1000,Merchants!$B$4:$B$1000,"Not found") | D898: =XLOOKUP(A898,tblInvoices[invoice_id],tblInvoices[expected_fee]) | E898: =XLOOKUP(A898,tblInvoices[invoice_id],tblInvoices[billed_fee]) | F898: =E898-D898 | G898: =IF(D898=0,0,ROUND(100*F898/D898,2)) | H898: =IF(ABS(F898)<=0.01,"Correct",IF(F898<0,"Underbilled","Overbilled"))

Sheet AR Aging
A1: AR Aging - SUMIFS against Payments, aging bucket via IFS
A2: As-of date: 2026-08-13
A4: invoice_id | B4: merchant_id | C4: merchant_name | D4: due_date | E4: total_invoice_amount | F4: total_paid | G4: outstanding_amount | H4: days_overdue | I4: aging_bucket
A5: INV0000956 | B5: MER00048 | C5: =XLOOKUP(B5,Merchants!$A$4:$A$1000,Merchants!$B$4:$B$1000,"Not found") | D5: =XLOOKUP(A5,tblInvoices[invoice_id],tblInvoices[due_date]) | E5: =XLOOKUP(A5,tblInvoices[invoice_id],tblInvoices[total_invoice_amount]) | F5: =SUMIFS(tblPayments[payment_amount],tblPayments[invoice_id],A5,tblPayments[payment_status],"Success") | G5: =MAX(0,E5-F5) | H5: =DATE(2026,8,13)-D5 | I5: =IFS(G5=0,"Excluded (paid)",H5<=0,"Current",H5<=30,"1-30 days",H5<=60,"31-60 days",H5<=90,"61-90 days",TRUE,"90+ days")
A6: INV0000957 | B6: MER00048 | C6: =XLOOKUP(B6,Merchants!$A$4:$A$1000,Merchants!$B$4:$B$1000,"Not found") | D6: =XLOOKUP(A6,tblInvoices[invoice_id],tblInvoices[due_date]) | E6: =XLOOKUP(A6,tblInvoices[invoice_id],tblInvoices[total_invoice_amount]) | F6: =SUMIFS(tblPayments[payment_amount],tblPayments[invoice_id],A6,tblPayments[payment_status],"Success") | G6: =MAX(0,E6-F6) | H6: =DATE(2026,8,13)-D6 | I6: =IFS(G6=0,"Excluded (paid)",H6<=0,"Current",H6<=30,"1-30 days",H6<=60,"31-60 days",H6<=90,"61-90 days",TRUE,"90+ days")
A7: INV0000958 | B7: MER00048 | C7: =XLOOKUP(B7,Merchants!$A$4:$A$1000,Merchants!$B$4:$B$1000,"Not found") | D7: =XLOOKUP(A7,tblInvoices[invoice_id],tblInvoices[due_date]) | E7: =XLOOKUP(A7,tblInvoices[invoice_id],tblInvoices[total_invoice_amount]) | F7: =SUMIFS(tblPayments[payment_amount],tblPayments[invoice_id],A7,tblPayments[payment_status],"Success") | G7: =MAX(0,E7-F7) | H7: =DATE(2026,8,13)-D7 | I7: =IFS(G7=0,"Excluded (paid)",H7<=0,"Current",H7<=30,"1-30 days",H7<=60,"31-60 days",H7<=90,"61-90 days",TRUE,"90+ days")
A8: INV0000959 | B8: MER00048 | C8: =XLOOKUP(B8,Merchants!$A$4:$A$1000,Merchants!$B$4:$B$1000,"Not found") | D8: =XLOOKUP(A8,tblInvoices[invoice_id],tblInvoices[due_date]) | E8: =XLOOKUP(A8,tblInvoices[invoice_id],tblInvoices[total_invoice_amount]) | F8: =SUMIFS(tblPayments[payment_amount],tblPayments[invoice_id],A8,tblPayments[payment_status],"Success") | G8: =MAX(0,E8-F8) | H8: =DATE(2026,8,13)-D8 | I8: =IFS(G8=0,"Excluded (paid)",H8<=0,"Current",H8<=30,"1-30 days",H8<=60,"31-60 days",H8<=90,"61-90 days",TRUE,"90+ days")
A9: INV0000960 | B9: MER00048 | C9: =XLOOKUP(B9,Merchants!$A$4:$A$1000,Merchants!$B$4:$B$1000,"Not found") | D9: =XLOOKUP(A9,tblInvoices[invoice_id],tblInvoices[due_date]) | E9: =XLOOKUP(A9,tblInvoices[invoice_id],tblInvoices[total_invoice_amount]) | F9: =SUMIFS(tblPayments[payment_amount],tblPayments[invoice_id],A9,tblPayments[payment_status],"Success") | G9: =MAX(0,E9-F9) | H9: =DATE(2026,8,13)-D9 | I9: =IFS(G9=0,"Excluded (paid)",H9<=0,"Current",H9<=30,"1-30 days",H9<=60,"31-60 days",H9<=90,"61-90 days",TRUE,"90+ days")
A10: INV0000961 | B10: MER00048 | C10: =XLOOKUP(B10,Merchants!$A$4:$A$1000,Merchants!$B$4:$B$1000,"Not found") | D10: =XLOOKUP(A10,tblInvoices[invoice_id],tblInvoices[due_date]) | E10: =XLOOKUP(A10,tblInvoices[invoice_id],tblInvoices[total_invoice_amount]) | F10: =SUMIFS(tblPayments[payment_amount],tblPayments[invoice_id],A10,tblPayments[payment_status],"Success") | G10: =MAX(0,E10-F10) | H10: =DATE(2026,8,13)-D10 | I10: =IFS(G10=0,"Excluded (paid)",H10<=0,"Current",H10<=30,"1-30 days",H10<=60,"31-60 days",H10<=90,"61-90 days",TRUE,"90+ days")
A11: INV0000962 | B11: MER00048 | C11: =XLOOKUP(B11,Merchants!$A$4:$A$1000,Merchants!$B$4:$B$1000,"Not found") | D11: =XLOOKUP(A11,tblInvoices[invoice_id],tblInvoices[due_date]) | E11: =XLOOKUP(A11,tblInvoices[invoice_id],tblInvoices[total_invoice_amount]) | F11: =SUMIFS(tblPayments[payment_amount],tblPayments[invoice_id],A11,tblPayments[payment_status],"Success") | G11: =MAX(0,E11-F11) | H11: =DATE(2026,8,13)-D11 | I11: =IFS(G11=0,"Excluded (paid)",H11<=0,"Current",H11<=30,"1-30 days",H11<=60,"31-60 days",H11<=90,"61-90 days",TRUE,"90+ days")
A12: INV0000963 | B12: MER00048 | C12: =XLOOKUP(B12,Merchants!$A$4:$A$1000,Merchants!$B$4:$B$1000,"Not found") | D12: =XLOOKUP(A12,tblInvoices[invoice_id],tblInvoices[due_date]) | E12: =XLOOKUP(A12,tblInvoices[invoice_id],tblInvoices[total_invoice_amount]) | F12: =SUMIFS(tblPayments[payment_amount],tblPayments[invoice_id],A12,tblPayments[payment_status],"Success") | G12: =MAX(0,E12-F12) | H12: =DATE(2026,8,13)-D12 | I12: =IFS(G12=0,"Excluded (paid)",H12<=0,"Current",H12<=30,"1-30 days",H12<=60,"31-60 days",H12<=90,"61-90 days",TRUE,"90+ days")
A13: INV0000964 | B13: MER00048 | C13: =XLOOKUP(B13,Merchants!$A$4:$A$1000,Merchants!$B$4:$B$1000,"Not found") | D13: =XLOOKUP(A13,tblInvoices[invoice_id],tblInvoices[due_date]) | E13: =XLOOKUP(A13,tblInvoices[invoice_id],tblInvoices[total_invoice_amount]) | F13: =SUMIFS(tblPayments[payment_amount],tblPayments[invoice_id],A13,tblPayments[payment_status],"Success") | G13: =MAX(0,E13-F13) | H13: =DATE(2026,8,13)-D13 | I13: =IFS(G13=0,"Excluded (paid)",H13<=0,"Current",H13<=30,"1-30 days",H13<=60,"31-60 days",H13<=90,"61-90 days",TRUE,"90+ days")
A14: INV0000965 | B14: MER00048 | C14: =XLOOKUP(B14,Merchants!$A$4:$A$1000,Merchants!$B$4:$B$1000,"Not found") | D14: =XLOOKUP(A14,tblInvoices[invoice_id],tblInvoices[due_date]) | E14: =XLOOKUP(A14,tblInvoices[invoice_id],tblInvoices[total_invoice_amount]) | F14: =SUMIFS(tblPayments[payment_amount],tblPayments[invoice_id],A14,tblPayments[payment_status],"Success") | G14: =MAX(0,E14-F14) | H14: =DATE(2026,8,13)-D14 | I14: =IFS(G14=0,"Excluded (paid)",H14<=0,"Current",H14<=30,"1-30 days",H14<=60,"31-60 days",H14<=90,"61-90 days",TRUE,"90+ days")
A15: INV0000966 | B15: MER00048 | C15: =XLOOKUP(B15,Merchants!$A$4:$A$1000,Merchants!$B$4:$B$1000,"Not found") | D15: =XLOOKUP(A15,tblInvoices[invoice_id],tblInvoices[due_date]) | E15: =XLOOKUP(A15,tblInvoices[invoice_id],tblInvoices[total_invoice_amount]) | F15: =SUMIFS(tblPayments[payment_amount],tblPayments[invoice_id],A15,tblPayments[payment_status],"Success") | G15: =MAX(0,E15-F15) | H15: =DATE(2026,8,13)-D15 | I15: =IFS(G15=0,"Excluded (paid)",H15<=0,"Current",H15<=30,"1-30 days",H15<=60,"31-60 days",H15<=90,"61-90 days",TRUE,"90+ days")
A16: INV0000967 | B16: MER00048 | C16: =XLOOKUP(B16,Merchants!$A$4:$A$1000,Merchants!$B$4:$B$1000,"Not found") | D16: =XLOOKUP(A16,tblInvoices[invoice_id],tblInvoices[due_date]) | E16: =XLOOKUP(A16,tblInvoices[invoice_id],tblInvoices[total_invoice_amount]) | F16: =SUMIFS(tblPayments[payment_amount],tblPayments[invoice_id],A16,tblPayments[payment_status],"Success") | G16: =MAX(0,E16-F16) | H16: =DATE(2026,8,13)-D16 | I16: =IFS(G16=0,"Excluded (paid)",H16<=0,"Current",H16<=30,"1-30 days",H16<=60,"31-60 days",H16<=90,"61-90 days",TRUE,"90+ days")
... A899: INV0019140 | B899: MER00902 | C899: =XLOOKUP(B899,Merchants!$A$4:$A$1000,Merchants!$B$4:$B$1000,"Not found") | D899: =XLOOKUP(A899,tblInvoices[invoice_id],tblInvoices[due_date]) | E899: =XLOOKUP(A899,tblInvoices[invoice_id],tblInvoices[total_invoice_amount]) | F899: =SUMIFS(tblPayments[payment_amount],tblPayments[invoice_id],A899,tblPayments[payment_status],"Success") | G899: =MAX(0,E899-F899) | H899: =DATE(2026,8,13)-D899 | I899: =IFS(G899=0,"Excluded (paid)",H899<=0,"Current",H899<=30,"1-30 days",H899<=60,"31-60 days",H899<=90,"61-90 days",TRUE,"90+ days")
A902: Aging Summary
A903: Bucket | B903: Invoice Count | C903: Total Outstanding
A904: Current | B904: =COUNTIFS(I5:I899,A904) | C904: =SUMIFS(G5:G899,I5:I899,A904)
A905: 1-30 days | B905: =COUNTIFS(I5:I899,A905) | C905: =SUMIFS(G5:G899,I5:I899,A905)
A906: 31-60 days | B906: =COUNTIFS(I5:I899,A906) | C906: =SUMIFS(G5:G899,I5:I899,A906)
A907: 61-90 days | B907: =COUNTIFS(I5:I899,A907) | C907: =SUMIFS(G5:G899,I5:I899,A907)
A908: 90+ days | B908: =COUNTIFS(I5:I899,A908) | C908: =SUMIFS(G5:G899,I5:I899,A908)

Sheet Collections
A1: Collection Activity - with outcome-effectiveness SUMIFS/COUNTIFS summary
A3: collection_id | B3: merchant_id | C3: invoice_id | D3: activity_date | E3: activity_type | F3: contact_channel | G3: collector | H3: outcome | I3: promised_payment_date | J3: promised_amount | K3: notes
A4: COL0000558 | B4: MER00055 | C4: INV0001101 | D4: 45570 | E4: Reminder | F4: Email | G4: Nandini Rajan | H4: No Response | K4: Automated reminder sent for invoice INV0001101 due 2024-10-02.
A5: COL0000559 | B5: MER00055 | C5: INV0001101 | D5: 45583 | E5: Email | F5: Email | G5: Vivek Nair | H5: No Response | K5: Followed up via email regarding outstanding invoice INV0001101.
A6: COL0000560 | B6: MER00055 | C6: INV0001101 | D6: 45589 | E6: Phone | F6: Phone | G6: Amit Saxena | H6: No Response | K6: Called merchant to discuss overdue invoice INV0001101.
A7: COL0000561 | B7: MER00055 | C7: INV0001101 | D7: 45599 | E7: Escalation | F7: Phone | G7: Ritu Bansal | H7: Escalated | K7: Escalated invoice INV0001101 to account manager for non-payment.
A8: COL0000562 | B8: MER00055 | C8: INV0001102 | D8: 45603 | E8: Reminder | F8: Email | G8: Farhan Sheikh | H8: No Response | K8: Automated reminder sent for invoice INV0001102 due 2024-11-01.
A9: COL0000563 | B9: MER00055 | C9: INV0001102 | D9: 45616 | E9: Email | F9: Email | G9: Shweta Gupta | H9: No Response | K9: Followed up via email regarding outstanding invoice INV0001102.
A10: COL0000564 | B10: MER00055 | C10: INV0001102 | D10: 45628 | E10: Phone | F10: Phone | G10: Shweta Gupta | H10: No Response | K10: Called merchant to discuss overdue invoice INV0001102.
A11: COL0000565 | B11: MER00055 | C11: INV0001102 | D11: 45634 | E11: Escalation | F11: Phone | G11: Ritu Bansal | H11: Escalated | K11: Escalated invoice INV0001102 to account manager for non-payment.
A12: COL0000566 | B12: MER00055 | C12: INV0001102 | D12: 45642 | E12: Payment Promise | F12: WhatsApp | G12: Ritu Bansal | H12: No Response | I12: 45651 | J12: 614.61 | K12: Merchant committed to paying invoice INV0001102 by 2024-12-25.
A13: COL0000567 | B13: MER00055 | C13: INV0001103 | D13: 45637 | E13: Reminder | F13: Email | G13: Farhan Sheikh | H13: No Response | K13: Automated reminder sent for invoice INV0001103 due 2024-12-02.
A14: COL0000568 | B14: MER00055 | C14: INV0001103 | D14: 45649 | E14: Email | F14: Email | G14: Amit Saxena | H14: Promise to Pay | I14: 45657 | J14: 718.84 | K14: Followed up via email regarding outstanding invoice INV0001103.
A15: COL0000569 | B15: MER00055 | C15: INV0001103 | D15: 45663 | E15: Phone | F15: Phone | G15: Amit Saxena | H15: Promise to Pay | I15: 45668 | J15: 1216.84 | K15: Called merchant to discuss overdue invoice INV0001103.
A16: COL0000570 | B16: MER00055 | C16: INV0001103 | D16: 45677 | E16: Escalation | F16: Phone | G16: Amit Saxena | H16: No Response | K16: Escalated invoice INV0001103 to account manager for non-payment.
A17: COL0000571 | B17: MER00055 | C17: INV0001103 | D17: 45682 | E17: Payment Promise | F17: WhatsApp | G17: Shweta Gupta | H17: Promise to Pay | I17: 45688 | J17: 888.13 | K17: Merchant committed to paying invoice INV0001103 by 2025-01-31.
A18: COL0000572 | B18: MER00055 | C18: INV0001109 | D18: 45846 | E18: Reminder | F18: Email | G18: Sanjay Kumar | H18: No Response | K18: Automated reminder sent for invoice INV0001109 due 2025-07-02.
A19: COL0000573 | B19: MER00055 | C19: INV0001109 | D19: 45853 | E19: Email | F19: Email | G19: Manish Tiwari | H19: No Response | K19: Followed up via email regarding outstanding invoice INV0001109.
A20: COL0000574 | B20: MER00055 | C20: INV0001109 | D20: 45866 | E20: Phone | F20: Phone | G20: Anjali Desai | H20: No Response | K20: Called merchant to discuss overdue invoice INV0001109.
A21: COL0000575 | B21: MER00055 | C21: INV0001109 | D21: 45871 | E21: Escalation | F21: Phone | G21: Farhan Sheikh | H21: No Response | K21: Escalated invoice INV0001109 to account manager for non-payment.
A22: COL0000576 | B22: MER00055 | C22: INV0001110 | D22: 45875 | E22: Reminder | F22: Email | G22: Vivek Nair | H22: No Response | K22: Automated reminder sent for invoice INV0001110 due 2025-08-01.
A23: COL0000577 | B23: MER00055 | C23: INV0001110 | D23: 45880 | E23: Email | F23: Email | G23: Shweta Gupta | H23: Promise to Pay | I23: 45894 | J23: 475.4 | K23: Followed up via email regarding outstanding invoice INV0001110.
A24: COL0000578 | B24: MER00055 | C24: INV0001110 | D24: 45891 | E24: Phone | F24: Phone | G24: Farhan Sheikh | H24: Disputed | K24: Called merchant to discuss overdue invoice INV0001110.
A25: COL0000579 | B25: MER00055 | C25: INV0001110 | D25: 45902 | E25: Escalation | F25: Phone | G25: Shweta Gupta | H25: Payment Received | K25: Escalated invoice INV0001110 to account manager for non-payment.
A26: COL0000580 | B26: MER00055 | C26: INV0001112 | D26: 45938 | E26: Reminder | F26: Email | G26: Manish Tiwari | H26: No Response | K26: Automated reminder sent for invoice INV0001112 due 2025-10-02.
A27: COL0000581 | B27: MER00055 | C27: INV0001112 | D27: 45948 | E27: Email | F27: Email | G27: Vivek Nair | H27: Promise to Pay | I27: 45959 | J27: 666.58 | K27: Followed up via email regarding outstanding invoice INV0001112.
A28: COL0000582 | B28: MER00055 | C28: INV0001112 | D28: 45956 | E28: Phone | F28: Phone | G28: Nandini Rajan | H28: No Response | K28: Called merchant to discuss overdue invoice INV0001112.
A29: COL0000583 | B29: MER00055 | C29: INV0001112 | D29: 45966 | E29: Escalation | F29: Phone | G29: Ritu Bansal | H29: Disputed | K29: Escalated invoice INV0001112 to account manager for non-payment.
A30: COL0000584 | B30: MER00055 | C30: INV0001112 | D30: 45978 | E30: Payment Promise | F30: WhatsApp | G30: Vivek Nair | H30: No Response | I30: 45984 | J30: 910.27 | K30: Merchant committed to paying invoice INV0001112 by 2025-11-23.
A31: COL0000585 | B31: MER00055 | C31: INV0001114 | D31: 46002 | E31: Reminder | F31: Email | G31: Farhan Sheikh | H31: Promise to Pay | I31: 46014 | J31: 851.88 | K31: Automated reminder sent for invoice INV0001114 due 2025-12-02.
A32: COL0000586 | B32: MER00055 | C32: INV0001114 | D32: 46013 | E32: Email | F32: Email | G32: Anjali Desai | H32: No Response | K32: Followed up via email regarding outstanding invoice INV0001114.
A33: COL0000587 | B33: MER00055 | C33: INV0001114 | D33: 46023 | E33: Phone | F33: Phone | G33: Anjali Desai | H33: No Response | K33: Called merchant to discuss overdue invoice INV0001114.
A34: COL0000588 | B34: MER00055 | C34: INV0001120 | D34: 46181 | E34: Reminder | F34: Email | G34: Manish Tiwari | H34: Promise to Pay | I34: 46185 | J34: 1301.11 | K34: Automated reminder sent for invoice INV0001120 due 2026-06-01.
A35: COL0000589 | B35: MER00055 | C35: INV0001120 | D35: 46189 | E35: Email | F35: Email | G35: Manish Tiwari | H35: Promise to Pay | I35: 46201 | J35: 1222.28 | K35: Followed up via email regarding outstanding invoice INV0001120.
A36: COL0000590 | B36: MER00055 | C36: INV0001120 | D36: 46196 | E36: Phone | F36: Phone | G36: Shweta Gupta | H36: No Response | K36: Called merchant to discuss overdue invoice INV0001120.
A37: COL0000591 | B37: MER00055 | C37: INV0001120 | D37: 46205 | E37: Escalation | F37: Phone | G37: Shweta Gupta | H37: Disputed | K37: Escalated invoice INV0001120 to account manager for non-payment.
A38: COL0000592 | B38: MER00055 | C38: INV0001122 | D38: 46241 | E38: Reminder | F38: Email | G38: Shweta Gupta | H38: Promise to Pay | I38: 46244 | J38: 1609.59 | K38: Automated reminder sent for invoice INV0001122 due 2026-08-01.
A39: COL0000593 | B39: MER00055 | C39: INV0001122 | D39: 46249 | E39: Email | F39: Email | G39: Nandini Rajan | H39: No Response | K39: Followed up via email regarding outstanding invoice INV0001122.
A40: COL0000594 | B40: MER00055 | C40: INV0001122 | D40: 46257 | E40: Phone | F40: Phone | G40: Sanjay Kumar | H40: No Response | K40: Called merchant to discuss overdue invoice INV0001122.
A41: COL0000595 | B41: MER00055 | C41: INV0001122 | D41: 46264 | E41: Escalation | F41: Phone | G41: Anjali Desai | H41: Disputed | K41: Escalated invoice INV0001122 to account manager for non-payment.
...

Sheet Revenue Reconciliation
A1: Revenue Reconciliation - invoice vs. total payments, status via IFS
A3: invoice_id | B3: merchant_id | C3: total_invoice_amount | D3: total_paid | E3: variance | F3: reconciliation_status
A4: INV0000956 | B4: MER00048 | C4: =XLOOKUP(A4,tblInvoices[invoice_id],tblInvoices[total_invoice_amount]) | D4: =SUMIFS(tblPayments[payment_amount],tblPayments[invoice_id],A4,tblPayments[payment_status],"Success") | E4: =D4-C4 | F4: =IFS(D4=0,"MISSING_PAYMENT",ABS(E4)<=1,"MATCHED",E4>1,"AMOUNT_MISMATCH",TRUE,"PARTIAL")
A5: INV0000957 | B5: MER00048 | C5: =XLOOKUP(A5,tblInvoices[invoice_id],tblInvoices[total_invoice_amount]) | D5: =SUMIFS(tblPayments[payment_amount],tblPayments[invoice_id],A5,tblPayments[payment_status],"Success") | E5: =D5-C5 | F5: =IFS(D5=0,"MISSING_PAYMENT",ABS(E5)<=1,"MATCHED",E5>1,"AMOUNT_MISMATCH",TRUE,"PARTIAL")
A6: INV0000958 | B6: MER00048 | C6: =XLOOKUP(A6,tblInvoices[invoice_id],tblInvoices[total_invoice_amount]) | D6: =SUMIFS(tblPayments[payment_amount],tblPayments[invoice_id],A6,tblPayments[payment_status],"Success") | E6: =D6-C6 | F6: =IFS(D6=0,"MISSING_PAYMENT",ABS(E6)<=1,"MATCHED",E6>1,"AMOUNT_MISMATCH",TRUE,"PARTIAL")
A7: INV0000959 | B7: MER00048 | C7: =XLOOKUP(A7,tblInvoices[invoice_id],tblInvoices[total_invoice_amount]) | D7: =SUMIFS(tblPayments[payment_amount],tblPayments[invoice_id],A7,tblPayments[payment_status],"Success") | E7: =D7-C7 | F7: =IFS(D7=0,"MISSING_PAYMENT",ABS(E7)<=1,"MATCHED",E7>1,"AMOUNT_MISMATCH",TRUE,"PARTIAL")
A8: INV0000960 | B8: MER00048 | C8: =XLOOKUP(A8,tblInvoices[invoice_id],tblInvoices[total_invoice_amount]) | D8: =SUMIFS(tblPayments[payment_amount],tblPayments[invoice_id],A8,tblPayments[payment_status],"Success") | E8: =D8-C8 | F8: =IFS(D8=0,"MISSING_PAYMENT",ABS(E8)<=1,"MATCHED",E8>1,"AMOUNT_MISMATCH",TRUE,"PARTIAL")
A9: INV0000961 | B9: MER00048 | C9: =XLOOKUP(A9,tblInvoices[invoice_id],tblInvoices[total_invoice_amount]) | D9: =SUMIFS(tblPayments[payment_amount],tblPayments[invoice_id],A9,tblPayments[payment_status],"Success") | E9: =D9-C9 | F9: =IFS(D9=0,"MISSING_PAYMENT",ABS(E9)<=1,"MATCHED",E9>1,"AMOUNT_MISMATCH",TRUE,"PARTIAL")
A10: INV0000962 | B10: MER00048 | C10: =XLOOKUP(A10,tblInvoices[invoice_id],tblInvoices[total_invoice_amount]) | D10: =SUMIFS(tblPayments[payment_amount],tblPayments[invoice_id],A10,tblPayments[payment_status],"Success") | E10: =D10-C10 | F10: =IFS(D10=0,"MISSING_PAYMENT",ABS(E10)<=1,"MATCHED",E10>1,"AMOUNT_MISMATCH",TRUE,"PARTIAL")
A11: INV0000963 | B11: MER00048 | C11: =XLOOKUP(A11,tblInvoices[invoice_id],tblInvoices[total_invoice_amount]) | D11: =SUMIFS(tblPayments[payment_amount],tblPayments[invoice_id],A11,tblPayments[payment_status],"Success") | E11: =D11-C11 | F11: =IFS(D11=0,"MISSING_PAYMENT",ABS(E11)<=1,"MATCHED",E11>1,"AMOUNT_MISMATCH",TRUE,"PARTIAL")
A12: INV0000964 | B12: MER00048 | C12: =XLOOKUP(A12,tblInvoices[invoice_id],tblInvoices[total_invoice_amount]) | D12: =SUMIFS(tblPayments[payment_amount],tblPayments[invoice_id],A12,tblPayments[payment_status],"Success") | E12: =D12-C12 | F12: =IFS(D12=0,"MISSING_PAYMENT",ABS(E12)<=1,"MATCHED",E12>1,"AMOUNT_MISMATCH",TRUE,"PARTIAL")
A13: INV0000965 | B13: MER00048 | C13: =XLOOKUP(A13,tblInvoices[invoice_id],tblInvoices[total_invoice_amount]) | D13: =SUMIFS(tblPayments[payment_amount],tblPayments[invoice_id],A13,tblPayments[payment_status],"Success") | E13: =D13-C13 | F13: =IFS(D13=0,"MISSING_PAYMENT",ABS(E13)<=1,"MATCHED",E13>1,"AMOUNT_MISMATCH",TRUE,"PARTIAL")
A14: INV0000966 | B14: MER00048 | C14: =XLOOKUP(A14,tblInvoices[invoice_id],tblInvoices[total_invoice_amount]) | D14: =SUMIFS(tblPayments[payment_amount],tblPayments[invoice_id],A14,tblPayments[payment_status],"Success") | E14: =D14-C14 | F14: =IFS(D14=0,"MISSING_PAYMENT",ABS(E14)<=1,"MATCHED",E14>1,"AMOUNT_MISMATCH",TRUE,"PARTIAL")
A15: INV0000967 | B15: MER00048 | C15: =XLOOKUP(A15,tblInvoices[invoice_id],tblInvoices[total_invoice_amount]) | D15: =SUMIFS(tblPayments[payment_amount],tblPayments[invoice_id],A15,tblPayments[payment_status],"Success") | E15: =D15-C15 | F15: =IFS(D15=0,"MISSING_PAYMENT",ABS(E15)<=1,"MATCHED",E15>1,"AMOUNT_MISMATCH",TRUE,"PARTIAL")
... A898: INV0019140 | B898: MER00902 | C898: =XLOOKUP(A898,tblInvoices[invoice_id],tblInvoices[total_invoice_amount]) | D898: =SUMIFS(tblPayments[payment_amount],tblPayments[invoice_id],A898,tblPayments[payment_status],"Success") | E898: =D898-C898 | F898: =IFS(D898=0,"MISSING_PAYMENT",ABS(E898)<=1,"MATCHED",E898>1,"AMOUNT_MISMATCH",TRUE,"PARTIAL")

Sheet Monthly MIS
A1: Monthly MIS - billed revenue and invoice counts via SUMIFS/COUNTIFS on Invoices
A3: billing_period_start_month | B3: invoice_count | C3: expected_revenue | D3: billed_revenue | E3: revenue_variance | F3: period_start (helper) | G3: period_end (helper)
A4: 2024-08 | B4: =COUNTIFS(tblInvoices[billing_period_start],">="&F4,tblInvoices[billing_period_start],"<"&G4) | C4: =SUMIFS(tblInvoices[expected_fee],tblInvoices[billing_period_start],">="&F4,tblInvoices[billing_period_start],"<"&G4) | D4: =SUMIFS(tblInvoices[billed_fee],tblInvoices[billing_period_start],">="&F4,tblInvoices[billing_period_start],"<"&G4) | E4: =D4-C4 | F4: =DATE(VALUE(LEFT(A4,4)),VALUE(MID(A4,6,2)),1) | G4: =EDATE(F4,1)
A5: 2024-09 | B5: =COUNTIFS(tblInvoices[billing_period_start],">="&F5,tblInvoices[billing_period_start],"<"&G5) | C5: =SUMIFS(tblInvoices[expected_fee],tblInvoices[billing_period_start],">="&F5,tblInvoices[billing_period_start],"<"&G5) | D5: =SUMIFS(tblInvoices[billed_fee],tblInvoices[billing_period_start],">="&F5,tblInvoices[billing_period_start],"<"&G5) | E5: =D5-C5 | F5: =DATE(VALUE(LEFT(A5,4)),VALUE(MID(A5,6,2)),1) | G5: =EDATE(F5,1)
A6: 2024-10 | B6: =COUNTIFS(tblInvoices[billing_period_start],">="&F6,tblInvoices[billing_period_start],"<"&G6) | C6: =SUMIFS(tblInvoices[expected_fee],tblInvoices[billing_period_start],">="&F6,tblInvoices[billing_period_start],"<"&G6) | D6: =SUMIFS(tblInvoices[billed_fee],tblInvoices[billing_period_start],">="&F6,tblInvoices[billing_period_start],"<"&G6) | E6: =D6-C6 | F6: =DATE(VALUE(LEFT(A6,4)),VALUE(MID(A6,6,2)),1) | G6: =EDATE(F6,1)
A7: 2024-11 | B7: =COUNTIFS(tblInvoices[billing_period_start],">="&F7,tblInvoices[billing_period_start],"<"&G7) | C7: =SUMIFS(tblInvoices[expected_fee],tblInvoices[billing_period_start],">="&F7,tblInvoices[billing_period_start],"<"&G7) | D7: =SUMIFS(tblInvoices[billed_fee],tblInvoices[billing_period_start],">="&F7,tblInvoices[billing_period_start],"<"&G7) | E7: =D7-C7 | F7: =DATE(VALUE(LEFT(A7,4)),VALUE(MID(A7,6,2)),1) | G7: =EDATE(F7,1)
A8: 2024-12 | B8: =COUNTIFS(tblInvoices[billing_period_start],">="&F8,tblInvoices[billing_period_start],"<"&G8) | C8: =SUMIFS(tblInvoices[expected_fee],tblInvoices[billing_period_start],">="&F8,tblInvoices[billing_period_start],"<"&G8) | D8: =SUMIFS(tblInvoices[billed_fee],tblInvoices[billing_period_start],">="&F8,tblInvoices[billing_period_start],"<"&G8) | E8: =D8-C8 | F8: =DATE(VALUE(LEFT(A8,4)),VALUE(MID(A8,6,2)),1) | G8: =EDATE(F8,1)
A9: 2025-01 | B9: =COUNTIFS(tblInvoices[billing_period_start],">="&F9,tblInvoices[billing_period_start],"<"&G9) | C9: =SUMIFS(tblInvoices[expected_fee],tblInvoices[billing_period_start],">="&F9,tblInvoices[billing_period_start],"<"&G9) | D9: =SUMIFS(tblInvoices[billed_fee],tblInvoices[billing_period_start],">="&F9,tblInvoices[billing_period_start],"<"&G9) | E9: =D9-C9 | F9: =DATE(VALUE(LEFT(A9,4)),VALUE(MID(A9,6,2)),1) | G9: =EDATE(F9,1)
A10: 2025-02 | B10: =COUNTIFS(tblInvoices[billing_period_start],">="&F10,tblInvoices[billing_period_start],"<"&G10) | C10: =SUMIFS(tblInvoices[expected_fee],tblInvoices[billing_period_start],">="&F10,tblInvoices[billing_period_start],"<"&G10) | D10: =SUMIFS(tblInvoices[billed_fee],tblInvoices[billing_period_start],">="&F10,tblInvoices[billing_period_start],"<"&G10) | E10: =D10-C10 | F10: =DATE(VALUE(LEFT(A10,4)),VALUE(MID(A10,6,2)),1) | G10: =EDATE(F10,1)
A11: 2025-03 | B11: =COUNTIFS(tblInvoices[billing_period_start],">="&F11,tblInvoices[billing_period_start],"<"&G11) | C11: =SUMIFS(tblInvoices[expected_fee],tblInvoices[billing_period_start],">="&F11,tblInvoices[billing_period_start],"<"&G11) | D11: =SUMIFS(tblInvoices[billed_fee],tblInvoices[billing_period_start],">="&F11,tblInvoices[billing_period_start],"<"&G11) | E11: =D11-C11 | F11: =DATE(VALUE(LEFT(A11,4)),VALUE(MID(A11,6,2)),1) | G11: =EDATE(F11,1)
A12: 2025-04 | B12: =COUNTIFS(tblInvoices[billing_period_start],">="&F12,tblInvoices[billing_period_start],"<"&G12) | C12: =SUMIFS(tblInvoices[expected_fee],tblInvoices[billing_period_start],">="&F12,tblInvoices[billing_period_start],"<"&G12) | D12: =SUMIFS(tblInvoices[billed_fee],tblInvoices[billing_period_start],">="&F12,tblInvoices[billing_period_start],"<"&G12) | E12: =D12-C12 | F12: =DATE(VALUE(LEFT(A12,4)),VALUE(MID(A12,6,2)),1) | G12: =EDATE(F12,1)
A13: 2025-05 | B13: =COUNTIFS(tblInvoices[billing_period_start],">="&F13,tblInvoices[billing_period_start],"<"&G13) | C13: =SUMIFS(tblInvoices[expected_fee],tblInvoices[billing_period_start],">="&F13,tblInvoices[billing_period_start],"<"&G13) | D13: =SUMIFS(tblInvoices[billed_fee],tblInvoices[billing_period_start],">="&F13,tblInvoices[billing_period_start],"<"&G13) | E13: =D13-C13 | F13: =DATE(VALUE(LEFT(A13,4)),VALUE(MID(A13,6,2)),1) | G13: =EDATE(F13,1)
A14: 2025-06 | B14: =COUNTIFS(tblInvoices[billing_period_start],">="&F14,tblInvoices[billing_period_start],"<"&G14) | C14: =SUMIFS(tblInvoices[expected_fee],tblInvoices[billing_period_start],">="&F14,tblInvoices[billing_period_start],"<"&G14) | D14: =SUMIFS(tblInvoices[billed_fee],tblInvoices[billing_period_start],">="&F14,tblInvoices[billing_period_start],"<"&G14) | E14: =D14-C14 | F14: =DATE(VALUE(LEFT(A14,4)),VALUE(MID(A14,6,2)),1) | G14: =EDATE(F14,1)
A15: 2025-07 | B15: =COUNTIFS(tblInvoices[billing_period_start],">="&F15,tblInvoices[billing_period_start],"<"&G15) | C15: =SUMIFS(tblInvoices[expected_fee],tblInvoices[billing_period_start],">="&F15,tblInvoices[billing_period_start],"<"&G15) | D15: =SUMIFS(tblInvoices[billed_fee],tblInvoices[billing_period_start],">="&F15,tblInvoices[billing_period_start],"<"&G15) | E15: =D15-C15 | F15: =DATE(VALUE(LEFT(A15,4)),VALUE(MID(A15,6,2)),1) | G15: =EDATE(F15,1)
... A27: 2026-07 | B27: =COUNTIFS(tblInvoices[billing_period_start],">="&F27,tblInvoices[billing_period_start],"<"&G27) | C27: =SUMIFS(tblInvoices[expected_fee],tblInvoices[billing_period_start],">="&F27,tblInvoices[billing_period_start],"<"&G27) | D27: =SUMIFS(tblInvoices[billed_fee],tblInvoices[billing_period_start],">="&F27,tblInvoices[billing_period_start],"<"&G27) | E27: =D27-C27 | F27: =DATE(VALUE(LEFT(A27,4)),VALUE(MID(A27,6,2)),1) | G27: =EDATE(F27,1)
